Workbook

Sheet Practicantes
A2: CONTROL DE CONVENIOS PRACTICANTES | G2: =TODAY() -> 46086
O3: 1RA RENOVACION | R3: 2DA RENOVACION | U3: 3ERA RENOVACION | X3: 4TA RENOVACION
A4: N° | B4: DNI | C4: APELLIDOS Y NOMBRES | D4: CONDICION | E4: FECHA ING | F4: F. CAMBIO A PRO | G4: AÑO | H4: MES | I4: DIAS | J4: SEDE | K4: UNIVERSIDAD | L4: JEFE INMEDIATO | M4: GERENCIA | N4: F. RENOVACION | O4: INICIO | R4: RENOVACION | U4: RENOVACION | X4: RENOVACION | AA4: RENOVACION | AD4: RENOVACION | AG4: RENOVACION | AJ4: RENOVACION | AM4: NOTA
G5: AÑO | H5: MES | I5: DIAS | O5: FECHA INICIO | P5: FECHA TERMINO | Q5: OBSERVACION | R5: FECHA TERMINO | S5: TIEMPO DE CONTRATO | T5: OBSERVACION | U5: FECHA TERMINO | V5: TIEMPO DE CONTRATO | W5: OBSERVACION | X5: FECHA TERMINO | Y5: TIEMPO DE CONTRATO | Z5: OBSERVACION | AA5: FECHA TERMINO | AB5: TIEMPO DE CONTRATO | AC5: OBSERVACION | AD5: FECHA TERMINO | AE5: TIEMPO DE CONTRATO | AF5: OBSERVACION | AG5: FECHA TERMINO | AH5: TIEMPO DE CONTRATO | AI5: OBSERVACION | AJ5: FECHA TERMINO | AK5: TIEMPO DE CONTRATO | AL5: OBSERVACION
A7: 1 | B7: 70837056 | C7: PATRICIO SAMANEZ BIASEVHIC | D7: PRACTICANTE PREPROFESIONAL | E7: 44963 | F7: =VLOOKUP(B7,'[1]13.01.26'!$C$6:$C$60,1,) -> 70837056 | G7: =DATEDIF(E7,$G$2,"Y") -> 3 | H7: =DATEDIF(E7,$G$2,"YM") -> 0 | I7: =DATEDIF(E7,$G$2,"MD") -> 27 | J7: =VLOOKUP(B7,[2]METSO!$C$11:$AC$1009,27,) -> CRONOS | K7: UNIVERSIDAD DE LIMA | L7: =VLOOKUP(B7,[3]METSO!$C$11:$N$937,12,) -> PASSANO PAREDES, GONZALO | M7: =VLOOKUP(B7,[3]METSO!$C$11:$M$937,11,) -> MA SAM MARKETING | N7: =+AE7 -> 46239 | O7: 45144 | P7: 45327 | Q7: ACTUALIZADO | R7: 45328 | S7: 45509 | T7: ACTUALIZADO | U7: 45510 | V7: 45693 | W7: ACTUALIZADO | X7: 45694 | Y7: 45874 | Z7: ACTUALIZADO | AA7: 45875 | AB7: 46058 | AC7: ACTUALIZADO | AD7: 46059 | AE7: 46239 | AF7: ACTUALIZADO | AN7: =VLOOKUP(B7,'[4]BD PRAC 12.08'!B$6:B$40,1,) -> 70837056 | AO7: CRONOS
A8: =+A7+1 -> 2 | B8: 73490500 | C8: VIDAL HEIDINGER, BRINCEL | D8: PRACTICANTE PROFESIONAL | E8: 45721 | F8: =VLOOKUP(B8,'[1]13.01.26'!$C$6:$C$60,1,) -> 73490500 | G8: =DATEDIF(E8,$G$2,"Y") -> 1 | H8: =DATEDIF(E8,$G$2,"YM") -> 0 | I8: =DATEDIF(E8,$G$2,"MD") -> 0 | J8: =VLOOKUP(B8,[2]METSO!$C$11:$AC$1009,27,) -> CRONOS | K8: UNIVERSIDAD NACIONAL DE INGENIERÍA | L8: =VLOOKUP(B8,[3]METSO!$C$11:$N$937,12,) -> HUAMANI ROMANI, ELWIN FREDY | M8: =VLOOKUP(B8,[3]METSO!$C$11:$M$937,11,) -> TECHNICAL SALES SUPPORT | N8: =+S8 -> 46177 | O8: 45721 | P8: 46085 | Q8: ACTUALIZADO | R8: 46086 | S8: 46177 | T8: ACTUALIZADO | AN8: =VLOOKUP(B8,'[4]BD PRAC 12.08'!B$6:B$40,1,) -> 73490500 | AO8: CRONOS
A9: =+A8+1 -> 3 | B9: 70325675 | C9: ESTRADA MALPARTIDA, BREIDY EDMARA | D9: PRACTICANTE PROFESIONAL | E9: =+O9 -> 45935 | F9: =VLOOKUP(B9,'[1]13.01.26'!$C$6:$C$60,1,) -> 70325675 | G9: =DATEDIF(E9,$G$2,"Y") -> 0 | H9: =DATEDIF(E9,$G$2,"YM") -> 5 | I9: =DATEDIF(E9,$G$2,"MD") -> 0 | J9: =VLOOKUP(B9,[2]METSO!$C$11:$AC$1009,27,) -> VULCANO | K9: PONTIFICIA UNIVERSIDAD CATÓLICA DEL PERÚ | L9: =VLOOKUP(B9,[3]METSO!$C$11:$N$937,12,) -> YALICO MARIN, GERSON ELIAS | M9: =VLOOKUP(B9,[3]METSO!$C$11:$M$937,11,) -> CNS MILL LINING | N9: =+P9 -> 46116 | O9: 45935 | P9: 46116 | Q9: ACTUALIZADO | AN9: =VLOOKUP(B9,'[4]BD PRAC 12.08'!B$6:B$40,1,) -> 70325675 | AO9: VULCANO
A10: =+A9+1 -> 4 | B10: 73045853 | C10: OCAÑA GUERRERO, CLAUDIA MILAGROS | D10: PRACTICANTE PROFESIONAL | E10: 45404 | F10: =VLOOKUP(B10,'[1]13.01.26'!$C$6:$C$60,1,) -> 73045853 | G10: =DATEDIF(E10,$G$2,"Y") -> 1 | H10: =DATEDIF(E10,$G$2,"YM") -> 10 | I10: =DATEDIF(E10,$G$2,"MD") -> 11 | J10: =VLOOKUP(B10,[2]METSO!$C$11:$AC$1009,27,) -> CRONOS | K10: UNIVERSIDAD NACIONAL MAYOR DE SAN MARCOS | L10: =VLOOKUP(B10,[3]METSO!$C$11:$N$937,12,) -> STRUBE ARELLANO, ALEXANDER PATRICIO | M10: =VLOOKUP(B10,[3]METSO!$C$11:$M$937,11,) -> TECHNICAL SUPPORT | N10: =+V10 -> 46132 | O10: 45586 | P10: 45767 | Q10: ACTUALIZADO | R10: 45768 | S10: 45920 | T10: ACTUALIZADO | U10: 45921 | V10: 46132 | W10: ACTUALIZADO | AN10: =VLOOKUP(B10,'[4]BD PRAC 12.08'!B$6:B$40,1,) -> 73045853 | AO10: CRONOS
A11: =+A10+1 -> 5 | B11: 72393443 | C11: MELGAREJO SALAZAR, PAULA ROSA | D11: PRACTICANTE PROFESIONAL | E11: 45672 | F11: =VLOOKUP(B11,'[1]13.01.26'!$C$6:$C$60,1,) -> 72393443 | G11: =DATEDIF(E11,$G$2,"Y") -> 1 | H11: =DATEDIF(E11,$G$2,"YM") -> 1 | I11: =DATEDIF(E11,$G$2,"MD") -> 18 | J11: =VLOOKUP(B11,[2]METSO!$C$11:$AC$1009,27,) -> CRONOS | K11: UNIVERSIDAD NACIONAL MAYOR DE SAN MARCOS | L11: =VLOOKUP(B11,[3]METSO!$C$11:$N$937,12,) -> CACERES CAHUATA, NICK VANDICK | M11: =VLOOKUP(B11,[3]METSO!$C$11:$M$937,11,) -> MA SAM SITE ACCOUNT MANAGEMENT – NORTH PE | N11: =+S11 -> 46217 | O11: 45853 | P11: 46036 | Q11: ACTUALIZADO | R11: 46037 | S11: 46217 | T11: ACTUALIZADO | AN11: =VLOOKUP(B11,'[4]BD PRAC 12.08'!B$6:B$40,1,) -> #N/A | AO11: CRONOS
A12: =+A11+1 -> 6 | B12: 71533789 | C12: CARRASCO RANDRIANARISON, VALERIA | D12: PRACTICANTE PROFESIONAL | E12: 45658 | F12: =VLOOKUP(B12,'[1]13.01.26'!$C$6:$C$60,1,) -> 71533789 | G12: =DATEDIF(E12,$G$2,"Y") -> 1 | H12: =DATEDIF(E12,$G$2,"YM") -> 2 | I12: =DATEDIF(E12,$G$2,"MD") -> 4 | J12: =VLOOKUP(B12,[2]METSO!$C$11:$AC$1009,27,) -> CRONOS | K12: UNIVERSIDAD PERUANA DE CIENCIAS APLICADAS | L12: =VLOOKUP(B12,[3]METSO!$C$11:$N$937,12,) -> GARCIA REATEGUI, CARLOS JAVIER | M12: =VLOOKUP(B12,[3]METSO!$C$11:$M$937,11,) -> MA SAM HR | N12: =+V12 -> 46112 | O12: 45658 | P12: 45838 | Q12: ACTUALIZADO | R12: 45839 | S12: 46022 | T12: ACTUALIZADO | U12: 46023 | V12: 46112 | W12: ACTUALIZADO | AN12: =VLOOKUP(B12,'[4]BD PRAC 12.08'!B$6:B$40,1,) -> #N/A | AO12: CRONOS
A13: =+A12+1 -> 7 | B13: 74608117 | C13: SAN MARTIN AMORRORTU, MARIA PAULA | D13: PRACTICANTE PROFESIONAL | E13: 46037 | F13: =VLOOKUP(B13,'[1]13.01.26'!$C$6:$C$60,1,) -> 74608117 | G13: =DATEDIF(E13,$G$2,"Y") -> 0 | H13: =DATEDIF(E13,$G$2,"YM") -> 1 | I13: =DATEDIF(E13,$G$2,"MD") -> 18 | J13: =VLOOKUP(B13,[2]METSO!$C$11:$AC$1009,27,) -> CRONOS | K13: UNIVERSIDAD DE INGENERÍA Y TECNOLOGÍA | L13: =VLOOKUP(B13,[3]METSO!$C$11:$N$937,12,) -> PEZO SANCHEZ, JOE JOHNY | M13: =VLOOKUP(B13,[3]METSO!$C$11:$M$937,11,) -> SALES & SERVICE PE & NORTH | N13: =+P13 -> 46401 | O13: 46037 | P13: 46401 | Q13: ACTUALIZADO | AN13: =VLOOKUP(B13,'[4]BD PRAC 12.08'!B$6:B$40,1,) -> #N/A | AO13: CRONOS
A14: =+A13+1 -> 8 | B14: 76252906 | C14: VALENCIA CORNEJO , JOSELYN BRIYIT | D14: PRACTICANTE PROFESIONAL | E14: 45874 | F14: =VLOOKUP(B14,'[1]13.01.26'!$C$6:$C$60,1,) -> 76252906 | G14: =DATEDIF(E14,$G$2,"Y") -> 0 | H14: =DATEDIF(E14,$G$2,"YM") -> 7 | I14: =DATEDIF(E14,$G$2,"MD") -> 0 | J14: =VLOOKUP(B14,[2]METSO!$C$11:$AC$1009,27,) -> AREQUIPA | K14: UNIVERSIDAD TECNOLÓGICA DEL PERÚ | L14: =VLOOKUP(B14,[3]METSO!$C$11:$N$937,12,) -> GOMEZ SILVA, FERNANDO JAVIER | M14: =VLOOKUP(B14,[3]METSO!$C$11:$M$937,11,) -> TECHNICAL SALES SUPPORT | N14: =+S14 -> 46238 | O14: 45874 | P14: 45934 | Q14: ACTUALIZADO | R14: 45935 | S14: 46238 | T14: ACTUALIZADO | AN14: =VLOOKUP(B14,'[4]BD PRAC 12.08'!B$6:B$40,1,) -> #N/A | AO14: AREQUIPA
A15: =+A14+1 -> 9 | B15: 70753323 | C15: CALISAYA CARPIO, CHRISTIAN FERNANDO | D15: PRACTICANTE PROFESIONAL | E15: 45509 | F15: =VLOOKUP(B15,'[1]13.01.26'!$C$6:$C$60,1,) -> 70753323 | G15: =DATEDIF(E15,$G$2,"Y") -> 1 | H15: =DATEDIF(E15,$G$2,"YM") -> 7 | I15: =DATEDIF(E15,$G$2,"MD") -> 0 | J15: =VLOOKUP(B15,[2]METSO!$C$11:$AC$1009,27,) -> AREQUIPA | K15: UNIVERSIDAD CATÓLICA DE SANTA MARÍA | L15: =VLOOKUP(B15,[3]METSO!$C$11:$N$937,12,) -> GARCIA CHAVEZ, IDA LIZ | M15: =VLOOKUP(B15,[3]METSO!$C$11:$M$937,11,) -> CONSIGNMENT & OPA CONTRACTS | N15: =+S15 -> 46057 | O15: 45693 | P15: 45873 | Q15: ACTUALIZADO | R15: 45874 | S15: 46057 | T15: ACTUALIZADO | AN15: =VLOOKUP(B15,'[4]BD PRAC 12.08'!B$6:B$40,1,) -> #N/A | AO15: AREQUIPA
A16: =+A15+1 -> 10 | B16: 76130757 | C16: ISLA HUAMAN, MARIELENA ARACELI | D16: PRACTICANTE PROFESIONAL | E16: =+O16 -> 45905 | F16: =VLOOKUP(B16,'[1]13.01.26'!$C$6:$C$60,1,) -> 76130757 | G16: =DATEDIF(E16,$G$2,"Y") -> 0 | H16: =DATEDIF(E16,$G$2,"YM") -> 6 | I16: =DATEDIF(E16,$G$2,"MD") -> 0 | J16: =VLOOKUP(B16,[2]METSO!$C$11:$AC$1009,27,) -> CRONOS | K16: UNIVERSIDAD PERUANA DE CIENCIAS APLICADAS | L16: =VLOOKUP(B16,[3]METSO!$C$11:$N$937,12,) -> RIVERA YLASACA, RICARDO SANTOS | M16: =VLOOKUP(B16,[3]METSO!$C$11:$M$937,11,) -> MA SAM SALES & SERVICE PERU AND NORTH | N16: =+P16 -> 46269 | O16: 45905 | P16: 46269 | Q16: ACTUALIZADO | AN16: =VLOOKUP(B16,'[4]BD PRAC 12.08'!B$6:B$40,1,) -> #N/A | AO16: CRONOS
A17: =+A16+1 -> 11 | B17: 74757847 | C17: CUBA CANDIA, ELBER ANDRE | D17: PRACTICANTE PROFESIONAL | E17: 46058 | F17: =VLOOKUP(B17,'[1]13.01.26'!$C$6:$C$60,1,) -> 74757847 | G17: =DATEDIF(E17,$G$2,"Y") -> 0 | H17: =DATEDIF(E17,$G$2,"YM") -> 1 | I17: =DATEDIF(E17,$G$2,"MD") -> 0 | J17: =VLOOKUP(B17,[2]METSO!$C$11:$AC$1009,27,) -> CRONOS | K17: UNIVERSIDAD PERUANA DE CIENCIAS APLICADAS | L17: =VLOOKUP(B17,[3]METSO!$C$11:$N$937,12,) -> RIVERA YLASACA, RICARDO SANTOS | M17: =VLOOKUP(B17,[3]METSO!$C$11:$M$937,11,) -> MA SAM SALES & SERVICE PERU AND NORTH | N17: =+P17 -> 46422 | O17: 46058 | P17: 46422 | Q17: ACTUALIZADO | AN17: =VLOOKUP(B17,'[4]BD PRAC 12.08'!B$6:B$40,1,) -> #N/A | AO17: CRONOS
A18: =+A17+1 -> 12 | B18: 76815262 | C18: ESCOBAR VIVANCO, MEYLIN ROSALY | D18: PRACTICANTE PREPROFESIONAL | E18: 45509 | F18: =VLOOKUP(B18,'[1]13.01.26'!$C$6:$C$60,1,) -> 76815262 | G18: =DATEDIF(E18,$G$2,"Y") -> 1 | H18: =DATEDIF(E18,$G$2,"YM") -> 7 | I18: =DATEDIF(E18,$G$2,"MD") -> 0 | J18: =VLOOKUP(B18,[2]METSO!$C$11:$AC$1009,27,) -> CRONOS | K18: UNIVERSIDAD NACIONAL MAYOR DE SAN MARCOS | L18: =VLOOKUP(B18,[3]METSO!$C$11:$N$937,12,) -> VARGAS BELLINA, JOSE ANTONIO | M18: =VLOOKUP(B18,[3]METSO!$C$11:$M$937,11,) -> MA SAM SITE ACCOUNT MANAGEMENT – CENTER PE | N18: =+Y18 -> 46116 | O18: 45693 | P18: 45873 | Q18: ACTUALIZADO | R18: 45874 | S18: 45995 | T18: ACTUALIZADO | U18: 45996 | V18: 46085 | W18: ACTUALIZADO | X18: 46086 | Y18: 46116 | Z18: ACTUALIZADO | AN18: =VLOOKUP(B18,'[4]BD PRAC 12.08'!B$6:B$40,1,) -> #N/A | AO18: CRONOS
A19: =+CESADOS!A119+1 -> 14 | B19: 72915588 | C19: TREJO TAPIA, ALESSANDRO RIVELINO | D19: PRACTICANTE PREPROFESIONAL | E19: 45586 | F19: =VLOOKUP(B19,'[1]13.01.26'!$C$6:$C$60,1,) -> 72915588 | G19: =DATEDIF(E19,$G$2,"Y") -> 1 | H19: =DATEDIF(E19,$G$2,"YM") -> 4 | I19: =DATEDIF(E19,$G$2,"MD") -> 12 | J19: =VLOOKUP(B19,[2]METSO!$C$11:$AC$1009,27,) -> CRONOS | K19: UNIVERSIDAD NACIONAL DE INGENIERÍA | L19: =VLOOKUP(B19,[3]METSO!$C$11:$N$937,12,) -> GORVENIA GORVENIA, HILARIO DAMASO | M19: =VLOOKUP(B19,[3]METSO!$C$11:$M$937,11,) -> MA SAM MINERALS SALES | N19: =+S19 -> 46132 | O19: 45768 | P19: 45950 | Q19: ACTUALIZADO | R19: 45951 | S19: 46132 | T19: ACTUALIZADO | AO19: CRONOS
A20: =+CESADOS!A117+1 -> 16 | B20: 71042255 | C20: RUIZ HERRERA, MARICELA | D20: PRACTICANTE PREPROFESIONAL | E20: 45705 | F20: =VLOOKUP(B20,'[1]13.01.26'!$C$6:$C$60,1,) -> 71042255 | G20: =DATEDIF(E20,$G$2,"Y") -> 1 | H20: =DATEDIF(E20,$G$2,"YM") -> 0 | I20: =DATEDIF(E20,$G$2,"MD") -> 16 | J20: =VLOOKUP(B20,[2]METSO!$C$11:$AC$1009,27,) -> CRONOS | K20: ESAN | L20: =VLOOKUP(B20,[3]METSO!$C$11:$N$937,12,) -> SEPULVEDA, MARIA | M20: =VLOOKUP(B20,[3]METSO!$C$11:$M$937,11,) -> SVSGLO ORDER AND LOGISTICS OPERATIONS | N20: =+V20 -> 46250 | O20: 45705 | P20: 45885 | Q20: ACTUALIZADO | R20: 45886 | S20: 46069 | T20: ACTUALIZADO | U20: 46070 | V20: 46250 | W20: ACTUALIZADO | AO20: CRONOS
A21: =+A20+1 -> 17 | B21: 73859388 | C21: RAMOS NUÑEZ, ALEJANDRA DANIELA | D21: PRACTICANTE PREPROFESIONAL | E21: 45705 | F21: =VLOOKUP(B21,'[1]13.01.26'!$C$6:$C$60,1,) -> 73859388 | G21: =DATEDIF(E21,$G$2,"Y") -> 1 | H21: =DATEDIF(E21,$G$2,"YM") -> 0 | I21: =DATEDIF(E21,$G$2,"MD") -> 16 | J21: =VLOOKUP(B21,[2]METSO!$C$11:$AC$1009,27,) -> AREQUIPA | K21: UNIVERSIDAD CATÓLICA SAN PABLO | L21: =VLOOKUP(B21,[3]METSO!$C$11:$N$937,12,) -> CHAVEZ NAVARRO, JORGE | M21: =VLOOKUP(B21,[3]METSO!$C$11:$M$937,11,) -> TECHNICAL SALES SUPPORT | N21: =+V21 -> 46097 | O21: 45705 | P21: 45885 | Q21: ACTUALIZADO | R21: 45886 | S21: 46069 | T21: ACTUALIZADO | U21: 46070 | V21: 46097 | W21: ACTUALIZADO | AO21: AREQUIPA
A22: =+A21+1 -> 18 | B22: 76277533 | C22: VERGARA HERRERA, FABIÁN | D22: PRACTICANTE PROFESIONAL | E22: 46070 | F22: =VLOOKUP(B22,'[1]13.01.26'!$C$6:$C$60,1,) -> 76277533 | G22: =DATEDIF(E22,$G$2,"Y") -> 0 | H22: =DATEDIF(E22,$G$2,"YM") -> 0 | I22: =DATEDIF(E22,$G$2,"MD") -> 16 | J22: =VLOOKUP(B22,[2]METSO!$C$11:$AC$1009,27,) -> CRONOS | K22: UNIVERSIDAD DE LIMA | L22: =VLOOKUP(B22,[3]METSO!$C$11:$N$937,12,) -> ROJAS MAMANI, XIMENA ARACELY | M22: =VLOOKUP(B22,[3]METSO!$C$11:$M$937,11,) -> SVSS IPRO AMERICAS | N22: =+P22 -> 46434 | O22: 46070 | P22: 46434 | Q22: ACTUALIZADO | AO22: CRONOS
A23: =+A22+1 -> 19 | B23: 74898628 | C23: ALVARADO BENITES, WILLIAN JHOSUE | D23: PRACTICANTE PREPROFESIONAL | E23: 45705 | F23: =VLOOKUP(B23,'[1]13.01.26'!$C$6:$C$60,1,) -> 74898628 | G23: =DATEDIF(E23,$G$2,"Y") -> 1 | H23: =DATEDIF(E23,$G$2,"YM") -> 0 | I23: =DATEDIF(E23,$G$2,"MD") -> 16 | J23: =VLOOKUP(B23,[2]METSO!$C$11:$AC$1009,27,) -> LURIN | K23: UNIVERSIDAD DE LIMA | L23: =VLOOKUP(B23,[3]METSO!$C$11:$N$937,12,) -> VASQUEZ VERGARA, RODRIGO MANUEL | M23: =VLOOKUP(B23,[3]METSO!$C$11:$M$937,11,) -> MIN PUMPS OPERATIONS | N23: =+V23 -> 46250 | O23: 45705 | P23: 45885 | Q23: ACTUALIZADO | R23: 45886 | S23: 46069 | T23: ACTUALIZADO | U23: 46070 | V23: 46250 | W23: ACTUALIZADO | AO23: LURIN
A24: =+A23+1 -> 20 | B24: 47071597 | C24: VELA PEÑA, ROY ANDRE | D24: PRACTICANTE PROFESIONAL | E24: 46070 | F24: =VLOOKUP(B24,'[1]13.01.26'!$C$6:$C$60,1,) -> 47071597 | G24: =DATEDIF(E24,$G$2,"Y") -> 0 | H24: =DATEDIF(E24,$G$2,"YM") -> 0 | I24: =DATEDIF(E24,$G$2,"MD") -> 16 | J24: =VLOOKUP(B24,[2]METSO!$C$11:$AC$1009,27,) -> VULCANO | K24: UNIVERSIDAD NACIONAL MAYOR DE SAN MARCOS | L24: =VLOOKUP(B24,[3]METSO!$C$11:$N$937,12,) -> CONDOR MARCELO, HERNAN GERSON | M24: =VLOOKUP(B24,[3]METSO!$C$11:$M$937,11,) -> CNS RUBBER & POLYMET SUPPLY CHAIN | N24: =+P24 -> 46434 | O24: 46070 | P24: 46434 | Q24: ACTUALIZADO | AO24: VULCANO
A25: =+CESADOS!A118+1 -> 22 | B25: 73028901 | C25: ROSALES ANGELES, LUIS ANGEL MARXS | D25: PRACTICANTE PROFESIONAL | E25: 45917 | F25: =VLOOKUP(B25,'[1]13.01.26'!$C$6:$C$60,1,) -> 73028901 | G25: =DATEDIF(E25,$G$2,"Y") -> 0 | H25: =DATEDIF(E25,$G$2,"YM") -> 5 | I25: =DATEDIF(E25,$G$2,"MD") -> 16 | J25: =VLOOKUP(B25,[2]METSO!$C$11:$AC$1009,27,) -> CRONOS | K25: UNIVERSIDAD NACIONAL TECNOLÓGICA DE LIMA SUR | L25: =VLOOKUP(B25,[3]METSO!$C$11:$N$937,12,) -> MESCUA HUAMAN, FRANK JOSEP | M25: =VLOOKUP(B25,[3]METSO!$C$11:$M$937,11,) -> MA SAM SITE ACCOUNT MANAGEMENT – SOUTH PE | N25: =+S25 -> 46128 | O25: 45917 | P25: 46097 | Q25: ACTUALIZADO | R25: 46098 | S25: 46128 | T25: ACTUALIZADO | AO25: CRONOS
A26: =+A25+1 -> 23 | B26: 73073569 | C26: CURAY CORREA ANGELO ENMANUEL | D26: PRACTICANTE PREPROFESIONAL | E26: 45782 | F26: =VLOOKUP(B26,'[1]13.01.26'!$C$6:$C$60,1,) -> 73073569 | G26: =DATEDIF(E26,$G$2,"Y") -> 0 | H26: =DATEDIF(E26,$G$2,"YM") -> 10 | I26: =DATEDIF(E26,$G$2,"MD") -> 0 | J26: =VLOOKUP(B26,[2]METSO!$C$11:$AC$1009,27,) -> VULCANO | K26: PONTIFICIA UNIVERSIDAD CATÓLICA DEL PERÚ | L26: =VLOOKUP(B26,[3]METSO!$C$11:$N$937,12,) -> SILVA NUÑEZ, JHINO SANTOS | M26: =VLOOKUP(B26,[3]METSO!$C$11:$M$937,11,) -> CNS MILL LINING | N26: =+P26 -> 46146 | O26: 45966 | P26: 46146 | Q26: ACTUALIZADO | AO26: VULCANO
A27: =+A26+1 -> 24 | B27: 76205689 | C27: GARCIA MORON, SEBASTIAN JOSE | D27: PRACTICANTE PREPROFESIONAL | E27: 45810 | F27: =VLOOKUP(B27,'[1]13.01.26'!$C$6:$C$60,1,) -> 76205689 | G27: =DATEDIF(E27,$G$2,"Y") -> 0 | H27: =DATEDIF(E27,$G$2,"YM") -> 9 | I27: =DATEDIF(E27,$G$2,"MD") -> 3 | J27: =VLOOKUP(B27,[2]METSO!$C$11:$AC$1009,27,) -> CRONOS | K27: UNIVERSIDAD DE INGENERÍA Y TECNOLOGÍA | L27: =VLOOKUP(B27,[3]METSO!$C$11:$N$937,12,) -> GALLEGOS PAREDES, ROGELIO ALAN | M27: =VLOOKUP(B27,[3]METSO!$C$11:$M$937,11,) -> MA SAM SALES & SERVICE PERU AND NORTH | N27: =+S27 -> 46174 | O27: 45810 | P27: 45992 | Q27: ACTUALIZADO | R27: 45993 | S27: 46174 | T27: ACTUALIZADO | AO27: CRONOS
A28: =+A27+1 -> 25 | B28: 70358917 | C28: FELIX LIZAMA, RODRIGO SEBASTIAN | D28: PRACTICANTE PROFESIONAL | E28: 46083 | F28: =VLOOKUP(B28,'[1]13.01.26'!$C$6:$C$60,1,) -> 70358917 | G28: =DATEDIF(E28,$G$2,"Y") -> 0 | H28: =DATEDIF(E28,$G$2,"YM") -> 0 | I28: =DATEDIF(E28,$G$2,"MD") -> 3 | J28: =VLOOKUP(B28,[2]METSO!$C$11:$AC$1009,27,) -> CRONOS | K28: PONTIFICIA UNIVERSIDAD CATÓLICA DEL PERÚ | L28: =VLOOKUP(B28,[3]METSO!$C$11:$N$937,12,) -> YOVERA MELENDEZ, MARCO AURELIO | M28: =VLOOKUP(B28,[3]METSO!$C$11:$M$937,11,) -> MA SAM FSE & LCS PE | N28: =+P28 -> 46447 | O28: 46083 | P28: 46447 | Q28: ACTUALIZADO | AO28: CRONOS
A29: =+A28+1 -> 26 | B29: 72115629 | C29: KIYAN OSHIRO, ADRIANA AYUMI | D29: PRACTICANTE PROFESIONAL | E29: 45810 | F29: =VLOOKUP(B29,'[1]13.01.26'!$C$6:$C$60,1,) -> 72115629 | G29: =DATEDIF(E29,$G$2,"Y") -> 0 | H29: =DATEDIF(E29,$G$2,"YM") -> 9 | I29: =DATEDIF(E29,$G$2,"MD") -> 3 | J29: =VLOOKUP(B29,[2]METSO!$C$11:$AC$1009,27,) -> CRONOS | K29: UNIVERSIDAD DE LIMA | L29: =VLOOKUP(B29,[3]METSO!$C$11:$N$937,12,) -> MESCUA HUAMAN, FRANK JOSEP | M29: =VLOOKUP(B29,[3]METSO!$C$11:$M$937,11,) -> MA SAM SITE ACCOUNT MANAGEMENT – SOUTH PE | N29: =+S29 -> 46174 | O29: 45810 | P29: 45992 | Q29: ACTUALIZADO | R29: 45993 | S29: 46174 | T29: ACTUALIZADO | AO29: CRONOS
A30: =+A29+1 -> 27 | B30: 70675959 | C30: JIMENEZ LINARES, XAVIER AARON | D30: PRACTICANTE PROFESIONAL | E30: 45873 | F30: =VLOOKUP(B30,'[1]13.01.26'!$C$6:$C$60,1,) -> 70675959 | G30: =DATEDIF(E30,$G$2,"Y") -> 0 | H30: =DATEDIF(E30,$G$2,"YM") -> 7 | I30: =DATEDIF(E30,$G$2,"MD") -> 1 | J30: =VLOOKUP(B30,[2]METSO!$C$11:$AC$1009,27,) -> AREQUIPA | K30: UNIVERSIDAD CATÓLICA DE SANTA MARÍA | L30: =VLOOKUP(B30,[3]METSO!$C$11:$N$937,12,) -> BUTRON ZUÑIGA, BARRY GABRIEL | M30: =VLOOKUP(B30,[3]METSO!$C$11:$M$937,11,) -> MA SAM FSE & LCS PE | N30: =+S30 -> 46145 | O30: 45873 | P30: 46056 | Q30: ACTUALIZADO | R30: 46057 | S30: 46145 | T30: ACTUALIZADO | AO30: AREQUIPA
A31: =+A30+1 -> 28 | B31: 71248162 | C31: CERRON RAMOS, ANGGELA STHEFANIE | D31: PRACTICANTE PREPROFESIONAL | E31: 45887 | F31: =VLOOKUP(B31,'[1]13.01.26'!$C$6:$C$60,1,) -> 71248162 | J31: =VLOOKUP(B31,[2]METSO!$C$11:$AC$1009,27,) -> VULCANO | K31: UNIVERSIDAD PERUANA DE CIENCIAS APLICADAS | L31: =VLOOKUP(B31,[3]METSO!$C$11:$N$937,12,) -> SOBREVILLA ZEVALLOS, EDA | M31: =VLOOKUP(B31,[3]METSO!$C$11:$M$937,11,) -> CNS RUBBER & POLYMET SUPPLY CHAIN | N31: =+S31 -> 46251 | O31: 45887 | P31: 46070 | Q31: ACTUALIZADO | R31: 46071 | S31: 46251 | T31: ACTUALIZADO | AO31: VULCANO
A32: =+A31+1 -> 29 | B32: 72870174 | C32: TRUJILLO LUCANO, CARLOS JAVIER | D32: PRACTICANTE PROFESIONAL | E32: 45887 | F32: =VLOOKUP(B32,'[1]13.01.26'!$C$6:$C$60,1,) -> 72870174 | J32: =VLOOKUP(B32,[2]METSO!$C$11:$AC$1009,27,) -> CRONOS | K32: UNIVERSIDAD NACIONAL DE INGENIERÍA | L32: =VLOOKUP(B32,[3]METSO!$C$11:$N$937,12,) -> STRUBE ARELLANO, ALEXANDER PATRICIO | M32: =VLOOKUP(B32,[3]METSO!$C$11:$M$937,11,) -> TECHNICAL SALES SUPPORT | N32: =+S32 -> 46251 | O32: 45887 | P32: 46070 | Q32: ACTUALIZADO | R32: 46071 | S32: 46251 | T32: ACTUALIZADO | AO32: CRONOS
A33: =+A32+1 -> 30 | B33: 72397508 | C33: VIZA BAUTISTA, KAROL JIMENA | D33: PRACTICANTE PROFESIONAL | E33: 45887 | F33: =VLOOKUP(B33,'[1]13.01.26'!$C$6:$C$60,1,) -> 72397508 | J33: =VLOOKUP(B33,[2]METSO!$C$11:$AC$1009,27,) -> AREQUIPA | K33: UNIVERSIDAD NACIONAL DE SAN AGUSTIN | L33: =VLOOKUP(B33,[3]METSO!$C$11:$N$937,12,) -> COAHILA HUALLPA, EDGAR GIOVANI | M33: =VLOOKUP(B33,[3]METSO!$C$11:$M$937,11,) -> MA SAM REPAIRS CENTER PE | N33: =+S33 -> 46251 | O33: 45887 | P33: 46070 | Q33: ACTUALIZADO | R33: 46071 | S33: 46251 | T33: ACTUALIZADO | AO33: AREQUIPA
A34: =+A33+1 -> 31 | B34: 72526242 | C34: MOSTACERO ROJAS, CAMILA MILAGROS | D34: PRACTICANTE PROFESIONAL | E34: 45887 | F34: =VLOOKUP(B34,'[1]13.01.26'!$C$6:$C$60,1,) -> 72526242 | J34: =VLOOKUP(B34,[2]METSO!$C$11:$AC$1009,27,) -> CRONOS | K34: UNIVERSIDAD DE LIMA | L34: =VLOOKUP(B34,[3]METSO!$C$11:$N$937,12,) -> MENDEZ SENISSE, SANDRA INES | M34: =VLOOKUP(B34,[3]METSO!$C$11:$M$937,11,) -> MA SAM QEHS | N34: =+S34 -> 46251 | O34: 45887 | P34: 46070 | Q34: ACTUALIZADO | R34: 46071 | S34: 46251 | T34: ACTUALIZADO | AO34: CRONOS
A35: =+A34+1 -> 32 | B35: 75851055 | C35: VILLANUEVA ALARCON, NICOLE NAHOMI | D35: PRACTICANTE PROFESIONAL | E35: 46071 | F35: =VLOOKUP(B35,'[1]13.01.26'!$C$6:$C$60,1,) -> 75851055 | J35: =VLOOKUP(B35,[2]METSO!$C$11:$AC$1009,27,) -> CRONOS | K35: UNIVERSIDAD DE LIMA | L35: =VLOOKUP(B35,[3]METSO!$C$11:$N$937,12,) -> CELEDONIO BALABARCA, JACKELINE NIEVES | M35: =VLOOKUP(B35,[3]METSO!$C$11:$M$937,11,) -> MA SAM SERVICE COMMERCIAL SUPPORT | N35: =+P35 -> 46251 | O35: 46071 | P35: 46251 | Q35: ACTUALIZADO | AO35: CRONOS
A36: =+A35+1 -> 33 | B36: 72221090 | C36: GOMEZ GARCIA, ARLETH DEIDAMIA | D36: PRACTICANTE PREPROFESIONAL | E36: 45887 | F36: =VLOOKUP(B36,'[1]13.01.26'!$C$6:$C$60,1,) -> 72221090 | J36: =VLOOKUP(B36,[2]METSO!$C$11:$AC$1009,27,) -> CRONOS | K36: UNIVERSIDAD DE INGENERÍA Y TECNOLOGÍA | L36: =VLOOKUP(B36,[3]METSO!$C$11:$N$937,12,) -> VELA RUIZ JOSE OSWALDO | M36: =VLOOKUP(B36,[3]METSO!$C$11:$M$937,11,) -> MA SAM MINERALS SALES | N36: =+S36 -> 46251 | O36: 45887 | P36: 46070 | Q36: ACTUALIZADO | R36: 46071 | S36: 46251 | T36: ACTUALIZADO | AO36: CRONOS
A37: =+A36+1 -> 34 | B37: 70392023 | C37: QUISPE VASQUEZ, MAITE VALERIA | D37: PRACTICANTE PROFESIONAL | E37: 45887 | F37: =VLOOKUP(B37,'[1]13.01.26'!$C$6:$C$60,1,) -> 70392023 | J37: =VLOOKUP(B37,[2]METSO!$C$11:$AC$1009,27,) -> CRONOS | K37: PONTIFICIA UNIVERSIDAD CATÓLICA DEL PERÚ | L37: =VLOOKUP(B37,[3]METSO!$C$11:$N$937,12,) -> AVALOS ROSAS, MANUEL ANTONIO | M37: =VLOOKUP(B37,[3]METSO!$C$11:$M$937,11,) -> MA SAM FSE & LCS PE | N37: =+S37 -> 46251 | O37: 45887 | P37: 46070 | Q37: ACTUALIZADO | R37: 46071 | S37: 46251 | T37: ACTUALIZADO | AO37: CRONOS
A38: =+A37+1 -> 35 | B38: 75738331 | C38: NAPA HUALLANCA, EMANUEL ISAI | D38: PRACTICANTE PROFESIONAL | E38: 45887 | F38: =VLOOKUP(B38,'[1]13.01.26'!$C$6:$C$60,1,) -> 75738331 | J38: =VLOOKUP(B38,[2]METSO!$C$11:$AC$1009,27,) -> CRONOS | K38: UNIVERSIDAD PERUANA DE CIENCIAS APLICADAS | L38: =VLOOKUP(B38,[3]METSO!$C$11:$N$937,12,) -> VITERI VALIENTE, VANESSA CAROLINA | M38: =VLOOKUP(B38,[3]METSO!$C$11:$M$937,11,) -> SVSGLO ORDER AND LOGISTICS OPERATIONS | N38: =+S38 -> 46251 | O38: 45887 | P38: 46070 | Q38: ACTUALIZADO | R38: 46071 | S38: 46251 | T38: ACTUALIZADO | AO38: CRONOS
A39: =+A38+1 -> 36 | B39: 72836883 | C39: CERNA ARRIETA, MARIA FERNANDA | D39: PRACTICANTE PROFESIONAL | E39: 45887 | F39: =VLOOKUP(B39,'[1]13.01.26'!$C$6:$C$60,1,) -> 72836883 | J39: =VLOOKUP(B39,[2]METSO!$C$11:$AC$1009,27,) -> VULCANO | K39: UNIVERSIDAD CIENTIFICA DEL SUR | L39: =VLOOKUP(B39,[3]METSO!$C$11:$N$937,12,) -> BORJA LOPEZ, CARLOS OSCAR GIORDANO | M39: =VLOOKUP(B39,[3]METSO!$C$11:$M$937,11,) -> MA SAM FSE & LCS PE | N39: =+S39 -> 46251 | O39: 45887 | P39: 46070 | Q39: ACTUALIZADO | R39: 46071 | S39: 46251 | T39: ACTUALIZADO | AO39: VULCANO
A40: =+A39+1 -> 37 | B40: 72022246 | C40: GUIZADO MARCELO, VASCO ANTONIO | D40: PRACTICANTE PREPROFESIONAL | E40: 45887 | F40: =VLOOKUP(B40,'[1]13.01.26'!$C$6:$C$60,1,) -> 72022246 | J40: =VLOOKUP(B40,[2]METSO!$C$11:$AC$1009,27,) -> CRONOS | K40: UNIVERSIDAD DE LIMA | L40: =VLOOKUP(B40,[3]METSO!$C$11:$N$937,12,) -> GARCIA CHAVEZ, IDA LIZ | M40: =VLOOKUP(B40,[3]METSO!$C$11:$M$937,11,) -> CONSIGNMENT & OPA CONTRACTS | N40: =+S40 -> 46251 | O40: 45887 | P40: 46070 | Q40: ACTUALIZADO | R40: 46071 | S40: 46251 | T40: ACTUALIZADO | AO40: CRONOS
A41: =+A40+1 -> 38 | B41: 73540176 | C41: JUSCAMAITA MARDINI, ROYINA | D41: PRACTICANTE PROFESIONAL | E41: 45887 | F41: =VLOOKUP(B41,'[1]13.01.26'!$C$6:$C$60,1,) -> 73540176 | J41: =VLOOKUP(B41,[2]METSO!$C$11:$AC$1009,27,) -> CRONOS | K41: UNIVERSIDAD DE LIMA | L41: =VLOOKUP(B41,[3]METSO!$C$11:$N$937,12,) -> VERA RUIZ, MANUEL | M41: =VLOOKUP(B41,[3]METSO!$C$11:$M$937,11,) -> MA SAM PUMPS SALES | N41: =+S41 -> 46251 | O41: 45887 | P41: 46070 | Q41: ACTUALIZADO | R41: 46071 | S41: 46251 | T41: ACTUALIZADO | AO41: CRONOS
A42: =+A41+1 -> 39 | B42: 75250624 | C42: HUAMAN CARRILLO, URSULA MILAGROS | D42: PRACTICANTE PROFESIONAL | E42: 45901 | F42: =VLOOKUP(B42,'[1]13.01.26'!$C$6:$C$60,1,) -> 75250624 | J42: =VLOOKUP(B42,[2]METSO!$C$11:$AC$1009,27,) -> AREQUIPA | K42: UNIVERSIDAD TECNOLÓGICA DEL PERÚ | L42: =VLOOKUP(B42,[3]METSO!$C$11:$N$937,12,) -> LLERENA REVILLA, ISELA MARELY | M42: =VLOOKUP(B42,[3]METSO!$C$11:$M$937,11,) -> MA SAM FSE & LCS PE | N42: =+S42 -> 46173 | O42: 45901 | P42: 46081 | Q42: ACTUALIZADO | R42: 46082 | S42: 46173 | T42: ACTUALIZADO | AO42: AREQUIPA
...

Sheet Hoja1
B4: Condiciones | C4: INGRESO REGULAR METSO (Propuesta inicial) | D4: POSICIONES TASKFORCE QUELLAVECO ( Nueva Propuesta laboral)
D5: Coordinador/Administrador de contrato ( Residente) | E5: Supervisor de Seguridad | F5: Supervisor Mecánico | G5: Planificador Mecánico/electricista | H5: Coordinador OT | I5: Soporte Planner | J5: Soporte Catalogación | K5: Coordinador de Recursos | L5: Técnico Mecánico | M5: Mecánico -Soldador | N5: Almacenero | O5: Asistente Administrativo
B6: Seguro Médico EPS, cubierto al 100% para titulares y dependientes legales en plan adicional 1. | C6: SI | D6: SI | E6: SI | F6: SI | G6: SI | H6: SI | I6: SI | J6: SI | K6: SI | L6: NO | M6: NO | N6: NO | O6: NO
B7: Seguro Oncológico para el colaborador y su familia directa cubierto al 100% | C7: SI | D7: SI | E7: SI | F7: SI | G7: SI | H7: SI | I7: SI | J7: SI | K7: SI | L7: NO | M7: NO | N7: NO | O7: NO
B8: Seguro Vida Ley 100% costo Metso Outotec desde el 1er día. | C8: SI | D8: SI | E8: SI | F8: SI | G8: SI | H8: SI | I8: SI | J8: SI | K8: SI | L8: SI | M8: SI | N8: SI | O8: SI

Sheet CESADOS
A2: CODIGO | B2: DNI | C2: APELLIDOS Y NOMBRES | D2: CONDICION | E2: FECHA ING | F2: F. RENO VACION | G2: INICIO | J2: RENOVACION | M2: RENOVACION | P2: RENOVACION | S2: RENOVACION | V2: RENOVACION | Y2: RENOVACION | AB2: RENOVACION
A3: P238 | B3: 70282242 | C3: LADY LOYSSI LOPEZ CASTAÑEDA | D3: PRACTICANTE PROFESIONAL | E3: 44991 | F3: 45356 | G3: 45175 | H3: 45356 | I3: ACTUALIZADO
A4: P266 | B4: 73363457 | C4: JESUS ANTONIO CENAS RODRIGUEZ | D4: PRACTICANTE PROFESIONAL | E4: 45180 | F4: 45361
A5: P247 | B5: 70931111 | C5: JULIO CESAR LUJAN HUAMAN | D5: PRACTICANTE PROFESIONAL | E5: 45061 | F5: =+H5 -> 45336 | G5: 45245 | H5: 45336 | I5: ACTUALIZADO
A6: P241 | B6: 77071019 | C6: ARIANA NICOLE ABANTO GALVAN | D6: =VLOOKUP(B6,#REF!,1,) -> #REF! | E6: PRACTICANTE PROFESIONAL | F6: 45019 | G6: =+I6 -> 45384 | H6: 45202 | I6: 45384 | J6: ACTUALIZADO
A7: P260 | B7: 70329948 | C7: MARIA PIA ALDERETE FABIAN | D7: =VLOOKUP(B7,#REF!,1,) -> #REF! | E7: PRACTICANTE PREPROFESIONAL | F7: 45180 | G7: 45361
A8: P240 | B8: 70066836 | C8: GUADALUPE THALIA GUERRERO RAMOS | D8: =VLOOKUP(B8,#REF!,1,) -> #REF! | E8: PRACTICANTE PROFESIONAL | F8: 45019 | G8: =+I8 -> 45384 | H8: 45202 | I8: 45384 | J8: ACTUALIZADO
A9: P264 | B9: 75957765 | C9: JHOISSY DIANA HUAMÁN ROJAS | D9: =VLOOKUP(B9,#REF!,1,) -> #REF! | E9: PRACTICANTE PREPROFESIONAL | F9: 45180 | G9: 45361
A10: P242 | B10: 74078100 | C10: ROBERTO CARLOS PINEDA VILLANUEVA | D10: =VLOOKUP(B10,#REF!,1,) -> #REF! | E10: PRACTICANTE PROFESIONAL | F10: 45019 | G10: =+I10 -> 45384 | H10: 45202 | I10: 45384 | J10: ACTUALIZADO
A11: P267 | B11: 71123168 | C11: ALEJANDRO MARTIN SAAVEDRA FAJARDO | D11: =VLOOKUP(B11,#REF!,1,) -> #REF! | E11: PRACTICANTE PROFESIONAL | F11: 45180 | G11: 45361
A12: P259 | B12: 73322426 | C12: NADIA CRISTINA SANCHEZ PAZ | D12: =VLOOKUP(B12,#REF!,1,) -> #REF! | E12: PRACTICANTE PREPROFESIONAL | F12: =+I12 -> 45545 | G12: 45361 | H12: 45362 | I12: 45545 | J12: ENVIADO
A13: P219 | B13: 74763526 | C13: GUILLERMO DAVID TUPAYACHI MAMANI | D13: =VLOOKUP(B13,#REF!,1,) -> #REF! | E13: PRACTICANTE PROFESIONAL | F13: 44746 | G13: =+O13 -> 45385 | H13: 44930 | I13: 45110 | J13: ACTUALIZADO | K13: 45111 | L13: 45294 | M13: ACTUALIZADO | N13: 45295 | O13: 45385 | P13: PDT QUE FIRME
A14: =+CESADOS!A58+1 -> #REF! | B14: 71792844 | C14: CLAUDIA ISABEL NUÑEZ MOLINA | D14: PRACTICANTE PROFESIONAL | E14: 45033 | F14: =+H14 -> 45398 | G14: 45216 | H14: 45398 | I14: ACTUALIZADO
A15: =+CESADOS!A63+1 -> 2 | B15: 70462278 | C15: ARACELI CLAUDIA MAMANI PRADO | D15: PRACTICANTE PREPROFESIONAL | E15: 44867 | F15: =+K15 -> 45413 | G15: 45048 | H15: 45231 | I15: ACTUALIZADO | J15: 373950 | K15: 45413 | L15: ACTUALIZADO | M15: 45414 | N15: 45597 | O15: ACTUALIZADO
A16: =+CESADOS!A17+1 -> #REF! | B16: 70800684 | C16: DANIELA MILAGROS CUBAS MARREROS | D16: PRACTICANTE PROFESIONAL | E16: 45061 | F16: =+H16 -> 45426 | G16: 45245 | H16: 45426 | I16: ACTUALIZADO
A17: =+CESADOS!A14+1 -> #REF! | B17: 73035527 | C17: VICTOR ANDRE FRANCO QUIÑONEZ | D17: PRACTICANTE PROFESIONAL | E17: 45048 | F17: =+H17 -> 45413 | G17: 45232 | H17: 45413 | I17: ACTUALIZADO
A18: =+CESADOS!A22+1 -> #REF! | B18: 72463169 | C18: KATIUSKA MICHELLE PAREDES SALINAS | D18: PRACTICANTE PROFESIONAL | E18: 45180 | F18: =+K18 -> 45483 | G18: 45362 | H18: 45422 | I18: ACTUALIZADO | J18: 45423 | K18: 45483 | L18: ACTUALIZADO
A19: =+CESADOS!A24+1 -> #REF! | B19: 75083026 | C19: FRANCESCA MILUSKA SIERRALTA VILLANUEVA | D19: PRACTICANTE PROFESIONAL | E19: 45180 | F19: =VLOOKUP(B19,[5]METSO!B$641:B$665,1,) -> #N/A | G19: =DATEDIF(E19,Practicantes!$G$2,"Y") -> 2 | H19: =DATEDIF(E19,Practicantes!$G$2,"YM") -> 5 | I19: =DATEDIF(E19,Practicantes!$G$2,"MD") -> 22 | J19: =+L19 -> 45545 | K19: 45362 | L19: 45545 | M19: ACTUALIZADO
A20: =+CESADOS!A29+1 -> #REF! | B20: 71582745 | C20: KENDY ANTHONY TITO CARDENAS | D20: PRACTICANTE PROFESIONAL | E20: 45110 | G20: =DATEDIF(E20,Practicantes!$G$2,"Y") -> 2 | H20: =DATEDIF(E20,Practicantes!$G$2,"YM") -> 8 | I20: =DATEDIF(E20,Practicantes!$G$2,"MD") -> 2 | J20: =+R20 -> 45535 | K20: 45294 | L20: 45351 | M20: ACTUALIZADO | N20: 45352 | O20: 45473 | P20: ACTUALIZADO | Q20: 45474 | R20: 45535 | S20: ACTUALIZADO
A21: =+CESADOS!A27+1 -> #REF! | B21: 72526196 | C21: JOSE CHRISTIAN HUAMANI LOPEZ | D21: PRACTICANTE PROFESIONAL | E21: 45173 | G21: =DATEDIF(E21,Practicantes!$G$2,"Y") -> 2 | H21: =DATEDIF(E21,Practicantes!$G$2,"YM") -> 6 | I21: =DATEDIF(E21,Practicantes!$G$2,"MD") -> 1 | J21: 45538 | K21: 45355 | L21: 45538 | M21: ACTUALIZADO | AJ21: =VLOOKUP(B21,'[4]BD PRAC 12.08'!B$6:B$40,1,) -> 72526196
A22: =+CESADOS!A21+1 -> #REF! | B22: 72186385 | C22: FRANCISCO STEFANO CABA CORNEJO | D22: PRACTICANTE PROFESIONAL | E22: 45180 | G22: =DATEDIF(E22,Practicantes!$G$2,"Y") -> 2 | H22: =DATEDIF(E22,Practicantes!$G$2,"YM") -> 5 | I22: =DATEDIF(E22,Practicantes!$G$2,"MD") -> 22 | J22: =+L22 -> 45545 | K22: 45362 | L22: 45545 | M22: ENVIADO | AJ22: =VLOOKUP(B22,'[4]BD PRAC 12.08'!B$6:B$40,1,) -> 72186385
A23: =+CESADOS!A22+1 -> #REF! | B23: 71082261 | C23: VALERIA EMILIA PANTIGOZO MELGAR | D23: PRACTICANTE PROFESIONAL | E23: 45180 | G23: =DATEDIF(E23,Practicantes!$G$2,"Y") -> 2 | H23: =DATEDIF(E23,Practicantes!$G$2,"YM") -> 5 | I23: =DATEDIF(E23,Practicantes!$G$2,"MD") -> 22 | J23: =+L23 -> 45545 | K23: 45362 | L23: 45545 | M23: ENVIADO | AJ23: =VLOOKUP(B23,'[4]BD PRAC 12.08'!B$6:B$40,1,) -> 71082261
A24: =+CESADOS!A23+1 -> #REF! | B24: 72921523 | C24: THALIA NICOLLE VENTE COLAN | D24: PRACTICANTE PROFESIONAL | E24: 45180 | G24: =DATEDIF(E24,Practicantes!$G$2,"Y") -> 2 | H24: =DATEDIF(E24,Practicantes!$G$2,"YM") -> 5 | I24: =DATEDIF(E24,Practicantes!$G$2,"MD") -> 22 | J24: =+L24 -> 45545 | K24: 45362 | L24: 45545 | M24: ENVIADO | AJ24: =VLOOKUP(B24,'[4]BD PRAC 12.08'!B$6:B$40,1,) -> 72921523
A25: =+CESADOS!A33+1 -> #REF! | B25: 77529028 | C25: LUIS AARON CRUZADO MEZARINA | D25: PRACTICANTE PROFESIONAL | E25: 45180 | G25: =DATEDIF(E25,Practicantes!$G$2,"Y") -> 2 | H25: =DATEDIF(E25,Practicantes!$G$2,"YM") -> 5 | I25: =DATEDIF(E25,Practicantes!$G$2,"MD") -> 22 | J25: =+L25 -> 45545 | K25: 45362 | L25: 45545 | M25: ACTUALIZADO | AJ25: =VLOOKUP(B25,'[4]BD PRAC 12.08'!B$6:B$40,1,) -> 77529028
A26: =+CESADOS!A62+1 -> 4 | B26: 71857984 | C26: FERNANDA ANTUANE BEJARANO PAREDES | D26: PRACTICANTE PROFESIONAL | E26: 45187 | G26: =DATEDIF(E26,Practicantes!$G$2,"Y") -> 2 | H26: =DATEDIF(E26,Practicantes!$G$2,"YM") -> 5 | I26: =DATEDIF(E26,Practicantes!$G$2,"MD") -> 15 | J26: =+L26 -> 45552 | K26: 45369 | L26: 45552 | M26: ACTUALIZADO | AJ26: =VLOOKUP(B26,'[4]BD PRAC 12.08'!B$6:B$40,1,) -> 71857984
A27: =+CESADOS!A29+1 -> #REF! | B27: 72222148 | C27: KEVIN JAVIER SIERRA REDHEAD | D27: PRACTICANTE PROFESIONAL | E27: 45124 | F27: =VLOOKUP(B27,'[6]BD PRAC 04.09'!B$6:B$53,1,) -> #N/A | G27: =DATEDIF(E27,Practicantes!$G$2,"Y") -> 2 | H27: =DATEDIF(E27,Practicantes!$G$2,"YM") -> 7 | I27: =DATEDIF(E27,Practicantes!$G$2,"MD") -> 16 | J27: =+L27 -> 45489 | K27: 45308 | L27: 45489 | M27: ACTUALIZADO | N27: 45490 | O27: 45673 | P27: ACTUALIZADO | AJ27: =VLOOKUP(B27,'[4]BD PRAC 12.08'!B$6:B$40,1,) -> 72222148
A28: =+CESADOS!A104+1 -> 3 | B28: 70212608 | C28: BRUNO FABIAN MOLINA FLORES | D28: PRACTICANTE PROFESIONAL | E28: 45187 | F28: =VLOOKUP(B28,'[6]BD PRAC 04.09'!B$6:B$53,1,) -> 70212608 | G28: =DATEDIF(E28,Practicantes!$G$2,"Y") -> 2 | H28: =DATEDIF(E28,Practicantes!$G$2,"YM") -> 5 | I28: =DATEDIF(E28,Practicantes!$G$2,"MD") -> 15 | J28: =+L28 -> 45552 | K28: 45369 | L28: 45552 | M28: ACTUALIZADO | AJ28: =VLOOKUP(B28,'[4]BD PRAC 12.08'!B$6:B$40,1,) -> 70212608
A29: =+Practicantes!#REF!+1 -> #REF! | B29: 74580499 | C29: ERNESTO FRANCISCO COYA ROJAS | D29: PRACTICANTE PROFESIONAL | E29: 45082 | F29: =VLOOKUP(B29,'[6]BD PRAC 04.09'!B$6:B$53,1,) -> 74580499 | G29: =DATEDIF(E29,Practicantes!$G$2,"Y") -> 2 | H29: =DATEDIF(E29,Practicantes!$G$2,"YM") -> 9 | I29: =DATEDIF(E29,Practicantes!$G$2,"MD") -> 0 | J29: =+O29 -> 45629 | K29: 45265 | L29: 45447 | M29: ACTUALIZADO | N29: 45447 | O29: 45629 | P29: ACTUALIZADO | AJ29: =VLOOKUP(B29,'[4]BD PRAC 12.08'!B$6:B$40,1,) -> 74580499
A30: =+CESADOS!A48+1 -> #REF! | B30: 74810109 | C30: MARIÑOS GIL, EVELYN VALERIA | D30: PRACTICANTE PREPROFESIONAL | E30: 45523 | J30: 45706
A31: =+CESADOS!A62+1 -> 4 | B31: 70489252 | C31: RAFAEL ANGEL ASCARATE CORONEL | D31: PRACTICANTE PROFESIONAL | E31: 45208 | F31: =VLOOKUP(B31,'[6]BD PRAC 04.09'!B$6:B$53,1,) -> 70489252 | G31: =DATEDIF(E31,Practicantes!$G$2,"Y") -> 2 | H31: =DATEDIF(E31,Practicantes!$G$2,"YM") -> 4 | I31: =DATEDIF(E31,Practicantes!$G$2,"MD") -> 24 | J31: 45665 | K31: 45391 | L31: 45481 | M31: ACTUALIZADO | N31: 45482 | O31: 45512 | P31: ACTUALIZADO | Q31: 45513 | R31: 45543 | S31: ACTUALIZADO | T31: 45544 | U31: 45604 | V31: ACTUALIZADO | W31: 45605 | X31: 45665 | Y31: ACTUALIZADO | AJ31: =VLOOKUP(B31,'[4]BD PRAC 12.08'!B$6:B$40,1,) -> 70489252
A32: =+CESADOS!A84+1 -> 15 | B32: 72282715 | C32: PEREYRA LOPEZ, PAOLA ANDREA | D32: PRACTICANTE PROFESIONAL | E32: 45537 | F32: =VLOOKUP(B32,'[6]BD PRAC 04.09'!B$6:B$53,1,) -> #N/A | G32: =DATEDIF(E32,Practicantes!$G$2,"Y") -> 1 | J32: 45717
A33: =+CESADOS!A29+1 -> #REF! | B33: 74759828 | C33: GIANCARLO ALBERCA DIAZ | D33: PRACTICANTE PREPROFESIONAL | E33: 45180 | F33: =VLOOKUP(B33,'[6]BD PRAC 04.09'!B$6:B$53,1,) -> 74759828 | G33: =DATEDIF(E33,Practicantes!$G$2,"Y") -> 2 | H33: =DATEDIF(E33,Practicantes!$G$2,"YM") -> 5 | I33: =DATEDIF(E33,Practicantes!$G$2,"MD") -> 22 | J33: =+O33 -> 45636 | K33: 45362 | L33: 45545 | M33: ACTUALIZADO | N33: 45546 | O33: 45636 | P33: ACTUALIZADO | AJ33: =VLOOKUP(B33,'[4]BD PRAC 12.08'!B$6:B$40,1,) -> 74759828
A34: =+CESADOS!A119+1 -> 14 | B34: 77665142 | C34: VALDEZ GONZALES, DANIEL ADRIAN | D34: PRACTICANTE PROFESIONAL | E34: 45586
A35: =+A34+1 -> 15 | B35: 71533789 | C35: CARRASCO RANDRIANARISON, VALERIA | D35: PRACTICANTE PREPROFESIONAL | E35: 45505 | F35: =VLOOKUP(B35,'[6]BD PRAC 04.09'!B$6:B$53,1,) -> 71533789 | G35: =DATEDIF(E35,$G$2,"Y") -> #VALUE! | H35: =DATEDIF(E35,$G$2,"YM") -> #VALUE! | I35: =DATEDIF(E35,$G$2,"MD") -> #VALUE! | J35: 45657 | K35: 45658 | L35: 45838 | M35: ACTUALIZADO | AJ35: =VLOOKUP(B35,'[4]BD PRAC 12.08'!B$6:B$40,1,) -> #N/A
A36: =+A35+1 -> 16 | B36: 73056034 | C36: LEONARDO FABRICIO YUPANQUI MERA | D36: PRACTICANTE PREPROFESIONAL | E36: 45187 | F36: =VLOOKUP(B36,'[6]BD PRAC 04.09'!B$6:B$53,1,) -> 73056034 | G36: =DATEDIF(E36,$G$2,"Y") -> #VALUE! | H36: =DATEDIF(E36,$G$2,"YM") -> #VALUE! | I36: =DATEDIF(E36,$G$2,"MD") -> #VALUE! | J36: =+L36 -> 45552 | K36: 45369 | L36: 45552 | M36: ACTUALIZADO | N36: 45553 | O36: 45733 | P36: ACTUALIZADO | AJ36: =VLOOKUP(B36,'[4]BD PRAC 12.08'!B$6:B$40,1,) -> 73056034
A37: =+A36+1 -> 17 | B37: 72634496 | C37: RODRIGUEZ LOPEZ, JONATAN CALAYO | D37: PRACTICANTE PREPROFESIONAL | E37: 45327 | F37: =VLOOKUP(B37,'[6]BD PRAC 04.09'!B$6:B$53,1,) -> 72634496 | G37: =DATEDIF(E37,$G$2,"Y") -> #VALUE! | H37: =DATEDIF(E37,$G$2,"YM") -> #VALUE! | I37: =DATEDIF(E37,$G$2,"MD") -> #VALUE! | J37: =+L37 -> 45692 | K37: 45509 | L37: 45692 | M37: ACTUALIZADO | AJ37: =VLOOKUP(B37,'[4]BD PRAC 12.08'!B$6:B$40,1,) -> 72634496
A38: =+A37+1 -> 18 | B38: 72302489 | C38: DE LA PUENTE MOZOMBITE, BIANCA ANGIELIN | D38: PRACTICANTE PREPROFESIONAL | E38: 45509 | F38: =VLOOKUP(B38,'[6]BD PRAC 04.09'!B$6:B$53,1,) -> 72302489 | G38: =DATEDIF(E38,$G$2,"Y") -> #VALUE! | H38: =DATEDIF(E38,$G$2,"YM") -> #VALUE! | I38: =DATEDIF(E38,$G$2,"MD") -> #VALUE! | J38: 45692 | AJ38: =VLOOKUP(B38,'[4]BD PRAC 12.08'!B$6:B$40,1,) -> #N/A
A39: =+CESADOS!A102+1 -> 4 | B39: 75388557 | C39: LOZANO CELI, ARIANA MARICIELA | D39: PRACTICANTE PROFESIONAL | E39: 45327 | F39: =VLOOKUP(B39,'[6]BD PRAC 04.09'!B$6:B$53,1,) -> 75388557 | G39: =DATEDIF(E39,Practicantes!$G$2,"Y") -> 2 | H39: =DATEDIF(E39,Practicantes!$G$2,"YM") -> 1 | I39: =DATEDIF(E39,Practicantes!$G$2,"MD") -> 0 | J39: =+L39 -> 45692 | K39: 45509 | L39: 45692 | M39: ACTUALIZADO | AJ39: =VLOOKUP(B39,'[4]BD PRAC 12.08'!B$6:B$40,1,) -> 75388557
A40: =+A39+1 -> 5 | B40: 72506178 | C40: PORRAS DIAZ, DIEGO ALONSO | D40: PRACTICANTE PREPROFESIONAL | E40: 45509 | F40: =VLOOKUP(B40,'[6]BD PRAC 04.09'!B$6:B$53,1,) -> 72506178 | G40: =DATEDIF(E40,$G$2,"Y") -> #VALUE! | H40: =DATEDIF(E40,$G$2,"YM") -> #VALUE! | I40: =DATEDIF(E40,$G$2,"MD") -> #VALUE! | J40: 45692 | AJ40: =VLOOKUP(B40,'[4]BD PRAC 12.08'!B$6:B$40,1,) -> #N/A
A41: =+A40+1 -> 6 | B41: 74068282 | C41: ANTICONA ORURO, LUIS HOMAR | D41: PRACTICANTE PREPROFESIONAL | E41: 45509 | F41: =VLOOKUP(B41,'[6]BD PRAC 04.09'!B$6:B$53,1,) -> 74068282 | G41: =DATEDIF(E41,$G$2,"Y") -> #VALUE! | H41: =DATEDIF(E41,$G$2,"YM") -> #VALUE! | I41: =DATEDIF(E41,$G$2,"MD") -> #VALUE! | J41: 45692 | AJ41: =VLOOKUP(B41,'[4]BD PRAC 12.08'!B$6:B$40,1,) -> #N/A
...

Sheet RESUMEN
A2: CODIGO | B2: APELLIDOS Y NOMBRES | C2: CONDICION | D2: FECHA ING | E2: F. RENO | F2: observaciones | G2: JEFATURA | H2: TIME ACT-
E3: VACION
A4: P255 | B4: JOSE CHRISTIAN HUAMANI LOPEZ | C4: PRACTICANTE PROFESIONAL | D4: 45173 | E4: 45354 | F4: SOLO PUEDE RENOVAR 6 MESES MÁS Y CULMINA SUS PRACTICAS PRO | G4: PASTOR CASTILLO LIS | H4: 6 meses | I4: TIENE CONSTANCIA DE EGRESADO
A5: P234 | B5: GUILLERMO ENRIQUE VASQUEZ ALVAREZ | C5: PRACTICANTE PREPROFESIONAL | D5: 44900 | E5: 45355 | F5: PUEDE RENOVAR 3 MESES PREPROFESIONAL MIENTRAS TRAMITA CONSTANCIA DE EGRESADO | G5: VARGAS BELLINA JOSE ANTONIO | H5: 1 años, 3 meses y 0 días | I5: SEGUIMIENTO A CONSTANCIA DE EGRESADO
A6: P249 | B6: MELANIE MORENO RIGUETTI | C6: PRACTICANTE PREPROFESIONAL | D6: 45082 | E6: 45355 | F6: YA NO PUEDE RENOVAR COMO PRE, PASARIA A PROFESIONAL | G6: OSORIO LOBOS MARCELA ANDREA | H6: 9 meses
A7: P237 | B7: ELIZABETH VALERIA ROSALES MEIER | C7: PRACTICANTE PREPROFESIONAL | D7: 44991 | E7: 45356 | F7: PUEDE RENOVAR COMO PRACTICAS PRE ACTUALMENTE VIII | G7: VITERI VALIENTE, VANESSA CAROLINA | H7: 1 año | I7: PEDIR CARTA ACT.
A8: P238 | B8: LADY LOYSSI LOPEZ CASTAÑEDA | C8: PRACTICANTE PROFESIONAL | D8: 44991 | E8: 45356 | F8: YA NO PUEDE RENOVAR COMO PROFESIONAL | G8: VILLAFUERTE CORDOVA, CARLOS ADRIAN | H8: 1 año
A9: P265 | B9: LUIS AARON CRUZADO MEZARINA | C9: PRACTICANTE PROFESIONAL | D9: 45180 | E9: 45361 | F9: SOLO PUEDE RENOVAR 6 MESES MÁS Y CULMINA SUS PRACTICAS PRO | G9: BORJA LOPEZ CARLOS OSCAR GIORDANO | H9: 6 meses | I9: CUENTA CON BACHILLER
A10: P267 | B10: ALEJANDRO MARTIN SAAVEDRA FAJARDO | C10: PRACTICANTE PREPROFESIONAL | D10: 45180 | E10: 45361 | F10: PUEDE RENOVAR 3 MESES PREPROFESIONAL MIENTRAS TRAMITA CONSTANCIA DE EGRESADO | G10: BUTRON ZUÑIGA, BARRY GABRIEL | H10: 6 meses | I10: PEDIR CARTA ACT. | J10: SEGUIMIENTO DE CONSTANCIA DE EGRESADO
A11: P261 | B11: THALIA NICOLLE VENTE COLAN | C11: PRACTICANTE PROFESIONAL | D11: 45180 | E11: 45361 | F11: SOLO PUEDE RENOVAR 6 MESES MÁS Y CULMINA SUS PRACTICAS PRO | G11: KU CUADRA EDUARDO ALBERTO | H11: 6 meses | I11: CUENTA CON BACHILLER
A12: P256 | B12: FRANCISCO STEFANO CABA CORNEJO | C12: PRACTICANTE PROFESIONAL | D12: 45180 | E12: 45361 | F12: SOLO PUEDE RENOVAR 6 MESES MÁS Y CULMINA SUS PRACTICAS PRO | G12: LAMAS GARCIA, EMILIO MOISES | H12: 6 meses | I12: CUENTA CON BACHILLER
A13: P262 | B13: FRANCESCA MILUSKA SIERRALTA VILLANUEVA | C13: PRACTICANTE PROFESIONAL | D13: 45180 | E13: 45361 | F13: SOLO PUEDE RENOVAR 6 MESES MÁS Y CULMINA SUS PRACTICAS PRO | G13: LEON IDME, JANKARLOS DAVID | H13: 6 meses | I13: TIENE CONSTANCIA DE EGRESADO
A14: P260 | B14: MARIA PIA ALDERETE FABIAN | C14: PRACTICANTE PREPROFESIONAL | D14: 45180 | E14: 45361 | F14: PUEDE RENOVAR COMO PRACTICAS PRE, ACTUALMENTE IX CICLO | G14: MENDEZ SENISSE, SANDRA INES | H14: 6 meses | I14: PEDIR CARTA ACT.
A15: P259 | B15: NADIA CRISTINA SANCHEZ PAZ | C15: PRACTICANTE PREPROFESIONAL | D15: 45180 | E15: 45361 | F15: PUEDE RENOVAR COMO PRACTICAS PRE ACTUALMENTE X CICLO | G15: RIVERA YLASACA, RICARDO SANTOS | H15: 6 meses | I15: PEDIR CARTA ACT.
A16: P258 | B16: VALERIA EMILIA PANTIGOZO MELGAR | C16: PRACTICANTE PROFESIONAL | D16: 45180 | E16: 45361 | F16: SOLO PUEDE RENOVAR 6 MESES MÁS Y CULMINA SUS PRACTICAS PRO | G16: RODRIGUEZ QUIROZ JOHNNY GERALD | H16: 6 meses | I16: CUENTA CON BACHILLER
A17: P263 | B17: GIANCARLO ALBERCA DIAZ | C17: PRACTICANTE PREPROFESIONAL | D17: 45180 | E17: 45361 | F17: PUEDE RENOVAR COMO PRACTICAS PRE, ACTUALMENTE X CICLO | G17: ROJAS MORENO, SERGIO ANDRES | H17: 6 meses | I17: PEDIR CARTA ACT. | J17: SEGUIMIENTO DE CONSTANCIA DE EGRESADO
A18: P264 | B18: JHOISSY DIANA HUAMÁN ROJAS | C18: PRACTICANTE PREPROFESIONAL | D18: 45180 | E18: 45361 | F18: PUEDE RENOVAR COMO PRACTICAS PRE ACTUALMENTE X CICLO | G18: STRUBE ARELLANO, ALEXANDER PATRICIO | H18: 6 meses | I18: PEDIR CARTA ACT. | J18: SEGUIMIENTO DE CONSTANCIA DE EGRESADO
A19: P257 | B19: KATIUSKA MICHELLE PAREDES SALINAS | C19: PRACTICANTE PROFESIONAL | D19: 45180 | E19: 45361 | F19: SOLO PUEDE RENOVAR 6 MESES MÁS Y CULMINA SUS PRACTICAS PRO | G19: TOLENTINO FARIAS, GRIZZLY HANS | H19: 6 meses | I19: CUENTA CON BACHILLER
A20: P268 | B20: DANIEL JESUS ESCOBEDO GALLEGOS | C20: PRACTICANTE PREPROFESIONAL | D20: 45180 | E20: 45361 | F20: PUEDE RENOVAR COMO PRACTICAS PRE ACTUALMENTE X CICLO | G20: YALICO MARIN, GERSON ELIAS | H20: 6 meses | I20: PEDIR CARTA ACT.
A21: P266 | B21: JESUS ANTONIO CENAS RODRIGUEZ | C21: PRACTICANTE PROFESIONAL | D21: 45180 | E21: 45361 | F21: SOLO PUEDE RENOVAR 6 MESES MÁS Y CULMINA SUS PRACTICAS PRO | G21: YOVERA MELENDEZ, MARCO AURELIO | H21: 6 meses | I21: CUENTA CON BACHILLER
A22: P269 | B22: BRUNO FABIAN MOLINA FLORES | C22: PRACTICANTE PROFESIONAL | D22: 45187 | E22: 45368 | F22: SOLO PUEDE RENOVAR 6 MESES MÁS Y CULMINA SUS PRACTICAS PRO | G22: CORTEZ RODRIGUEZ, WILMAN RAFAEL | H22: 6 meses | I22: CUENTA CON BACHILLER
A23: P271 | B23: FERNANDA ANTUANE BEJARANO PAREDES | C23: PRACTICANTE PROFESIONAL | D23: 45187 | E23: 45368 | F23: SOLO PUEDE RENOVAR 6 MESES MÁS Y CULMINA SUS PRACTICAS PRO | G23: PEZO SANCHEZ, JOE JOHNY | H23: 6 meses | I23: PEDIR CONSTANCIA DE EGRESO, SOLO TIENE CARTA
A24: P270 | B24: LEONARDO FABRICIO YUPANQUI MERA | C24: PRACTICANTE PREPROFESIONAL | D24: 45187 | E24: 45368 | F24: PUEDE RENOVAR COMO PRACTICAS PRE, ACTUALMENTE CICLO IX | G24: RIVERA YLASACA, RICARDO SANTOS | H24: 6 meses | I24: PEDIR CARTA ACT.
A25: P239 | B25: ZAIRA JUANITA URRUTIA SANCHEZ | C25: PRACTICANTE PROFESIONAL | D25: 45005 | E25: 45370 | F25: SOLO PUEDE RENOVAR 6 MESES MÁS Y CULMINA SUS PRACTICAS PRO | G25: VARGAS BELLINA JOSE ANTONIO | H25: 1 año | I25: 6 como pre y 6 pro

Sheet TIME
C2: LIQUIDACION POR TIEMPO DE SERVICIOS
A4: APELLIDOS Y NOMBRES | D4: CALAMPA NAVARRO CESAR AUGUSTO KEVIN
A5: OCUPACION | D5: OPERARIO DE PRODUCCION | J5: años | K5: =DATEDIF($D$6,$K$8,"y") -> 0
A6: FECHA DE INGRESO | D6: 46098 | F6: =+D7-D6 -> 30 | J6: meses | K6: =DATEDIF($D$6,$K$8,"ym") -> 1
A7: FECHA DE CESE | D7: 46128 | J7: dias | K7: =DATEDIF($D$6,$K$8,"md") -> 0
A8: TIEMPO DE SERVICIOS | D8: =CONCATENATE(K5," ","años",","," ",K6," ","meses"," ","y"," ",K7," ","días") -> 0 años, 1 meses y 0 días | J8: 1 dia mas | K8: =+D7+1 -> 46129
A9: MOTIVO | D9: RENUNCIA
D12: 3 meses y 13 dias
D15: sub meses | E15: sub dias
D16: =1900/2/6*3 -> 475 | E16: =1900/2/180*13 -> 68.611111 | F16: =+D16+E16 -> 543.61111
E19: 2 meses | F19: 20 dias | G19: Fmrem
E20: 4 meses | F20: 11 dias | G20: souther
E21: 6 meses | F21: 23 dias | G21: Issa
E22: 43 meses | F22: 27 dias | G22: metso
E23: 4 AÑOS | F23: 5 MESES
F24: 2 MESES
E25: 4 AÑOS | F25: 7 MESES

Sheet HISTORIAL DE CESADOS 2024
C1: RELACIÓN DE CESADOS 2024 - PRACTICANTES
A4: N° | B4: DNI | C4: NOMBRE | D4: CARGO | E4: AREA | F4: JEFE | G4: FECHA DE CESE | H4: MOTIVO DE SALIDA
A5: 1 | B5: 70931111 | C5: LUJAN HUAMAN JULIO CESAR | D5: STUDENT INTERNAL | E5: MIN PUMPS OPERATIONS | F5: AGUIRRE MORI, RONALD TOMAS | G5: 45336 | H5: RENUNCIO, PARA TRABAJAR EN ANTAMINA
A6: =+A5+1 -> 2 | B6: 73363457 | C6: CENAS RODRIGUEZ JESUS ANTONIO | D6: STUDENT INTERNAL | E6: MA SAM FSE & LCS PE | F6: YOVERA MELENDEZ, MARCO AURELIO | G6: 45337 | H6: PASO A EMPLEADO
A7: =+A6+1 -> 3 | B7: 70282242 | C7: LOPEZ CASTAÑEDA LADY LOYSSI | D7: STUDENT INTERNAL | E7: VILLAFUERTE CORDOVA, CARLOS ADRIAN | F7: VILLAFUERTE CORDOVA, CARLOS ADRIAN | G7: 45356 | H7: TERMINO SU PRACTICAS PROFESIONALES
A8: =+A7+1 -> 4 | B8: 70329948 | C8: ALDERETE FABIAN MARIA PIA | D8: STUDENT INTERNAL | E8: MENDEZ SENISSE, SANDRA INES | F8: MENDEZ SENISSE, SANDRA INES | G8: 45361 | H8: TERMINO SU PRACTICAS PROFESIONALES
A9: =+A8+1 -> 5 | B9: 75957765 | C9: HUAMAN ROJAS JHOISSY DIANA | D9: STUDENT INTERNAL | E9: STRUBE ARELLANO, ALEXANDER PATRICIO | F9: STRUBE ARELLANO, ALEXANDER PATRICIO | G9: 45361 | H9: PASO COMO TERCERO
A10: =+A9+1 -> 6 | B10: 71123168 | C10: SAAVEDRA FAJARDO ALEJANDRO MARTIN | D10: STUDENT INTERNAL | E10: BUTRON ZUÑIGA, BARRY GABRIEL | F10: BUTRON ZUÑIGA, BARRY GABRIEL | G10: 45361 | H10: JEFATURA NO RENOVO
A11: =+A10+1 -> 7 | B11: 77071019 | C11: ABANTO GALVAN ARIANA NICOLE | D11: STUDENT INTERNAL | E11: POZO DIAZ JASON | F11: POZO DIAZ JASON | G11: 45384 | H11: NO RENOVO, PRACTICAS POR MEJORA OPORTUNIDAD EN EMPRESA INDUSTRIAL
A12: =+A11+1 -> 8 | B12: 70066836 | C12: GUERRERO RAMOS GUADALUPE THALIA | D12: STUDENT INTERNAL | E12: CARRANZA CABALLERO, ABRAHAM CESAR | F12: CARRANZA CABALLERO, ABRAHAM CESAR | G12: 45384 | H12: NO TUVO DOCUMENTACIÓN DE UNIVERSIDAD PARA RENOVAR COMO PROFESIONAL.
A13: =+A12+1 -> 9 | B13: 74078100 | C13: PINEDA VILLANUEVA ROBERTO CARLOS | D13: STUDENT INTERNAL | E13: LOPEZ MACHACA ABEL ALBERTO | F13: LOPEZ MACHACA ABEL ALBERTO | G13: 45384 | H13: TERMINO SU PRACTICAS PROFESIONALES
A14: =+A13+1 -> 10 | B14: 74763526 | C14: TUPAYACHI MAMANI GUILLERMO DAVID | D14: STUDENT INTERNAL | E14: TARAZONA PAZ HECTOR DIEGO | F14: TARAZONA PAZ HECTOR DIEGO | G14: 45385 | H14: GERENCIA SOLICITO SU NO RENOVACIÓN
A15: =+A14+1 -> 11 | B15: 73322426 | C15: SANCHEZ PAZ NADIA CRISTINA | D15: STUDENT INTERNAL | E15: RIVERA YLASACA, RICARDO SANTOS | F15: RIVERA YLASACA, RICARDO SANTOS | G15: 45386 | H15: TERMINO SU PRACTICAS PROFESIONALES
A16: =+A15+1 -> 12 | B16: 71792844 | C16: NUÑEZ MOLINA CLAUDIA ISABEL | D16: STUDENT INTERNAL | E16: ROCA RADO ARNALDO PERCY | F16: ROCA RADO ARNALDO PERCY | G16: 45398 | H16: JEFATURA NO RENOVO
A17: =+A16+1 -> 13 | B17: 73035527 | C17: FRANCO QUIÑONEZ VÍCTOR ANDRÉ | D17: STUDENT INTERNAL | E17: SVSGLO OPERATIONAL PURCHASING | F17: COLLADO BORGOÑO PATRICIA ANGELICA | G17: 45413 | H17: RENUNCIA
... A19: =+A18+1 -> 15 | B19: 70462278 | C19: ARACELI CLAUDIA MAMANI PRADO | D19: STUDENT INTERNAL | E19: MA SAM SERVICE COMMERCIAL SUPPORT | F19: CELEDONIO BALABARCA JACKELINE NIEVES | G19: 45433 | H19: PASA A EMPLEADO
A20: =+Practicantes!A7+1 -> 2 | B20: 76279624 | C20: ELIZABETH VALERIA ROSALES MEIER | D20: PRACTICANTE PROFESIONAL | E20: =+O20 -> 45417 | F20: =VLOOKUP(B20,'[6]BD PRAC 04.09'!B$6:B$53,1,) -> 76279624 | G20: =DATEDIF(E20,Practicantes!$G$2,"Y") -> 1 | H20: =DATEDIF(E20,Practicantes!$G$2,"YM") -> 10 | I20: =DATEDIF(E20,Practicantes!$G$2,"MD") -> 0 | J20: 45601 | K20: 45175 | L20: 45356 | M20: ACTUALIZADO | N20: 45357 | O20: 45417 | P20: ACTUALIZADO | Q20: 45418 | R20: 45601 | S20: ACTUALIZADO | AJ20: =VLOOKUP(B20,'[4]BD PRAC 12.08'!B$6:B$40,1,) -> 76279624
A21: =+Practicantes!A14+1 -> 9 | B21: 75190987 | C21: BASTIDAS JAIMES, CARLOMARIA | D21: PRACTICANTE PROFESIONAL | E21: 45509 | F21: =VLOOKUP(B21,'[6]BD PRAC 04.09'!B$6:B$53,1,) -> 75190987 | G21: =DATEDIF(E21,Practicantes!$G$2,"Y") -> 1 | H21: =DATEDIF(E21,Practicantes!$G$2,"YM") -> 7 | I21: =DATEDIF(E21,Practicantes!$G$2,"MD") -> 0 | J21: 45692 | AJ21: =VLOOKUP(B21,'[4]BD PRAC 12.08'!B$6:B$40,1,) -> #N/A

Sheet Hoja2
A2: N° | B2: NUMERO DE DOC | C2: CODIGO SAP2 | D2: AP. PATERNO | E2: AP. MATERNO | F2: NOMBRE | G2: SEDE3 | H2: SUBVENCIÓN
A3: 1 | B3: 74898628 | C3: 456078 | D3: ALVARADO | E3: BENITES | F3: WILLIAN JHOSUE | G3: LURIN | H3: 1700
A4: =+A3+1 -> 2 | B4: 74068282 | C4: 453165 | D4: ANTICONA | E4: ORURO | F4: LUIS HOMAR | G4: VULCANO | H4: 1600
A5: =+A4+1 -> 3 | B5: 75534527 | C5: 456146 | D5: AQUINO | E5: CARBAJAL | F5: SHEYLI THALIA | G5: CRONOS | H5: 1900
A6: =+A5+1 -> 4 | B6: 71305032 | C6: 456086 | D6: BORDA | E6: CARRASCO | F6: ANGELICA VALERIA | G6: AREQUIPA | H6: 1400
A7: =+A6+1 -> 5 | B7: 70753323 | C7: 453288 | D7: CALISAYA | E7: CARPIO | F7: CHRISTIAN FERNANDO | G7: AREQUIPA | H7: 1600
A8: =+A7+1 -> 6 | B8: 71533789 | C8: 453138 | D8: CARRASCO | E8: RANDRIANARISON | F8: VALERIA | G8: CRONOS | H8: 1900
A9: =+A8+1 -> 7 | B9: 72836883 | C9: 459638 | D9: CERNA | E9: ARRIETA | F9: MARIA FERNANDA | G9: VULCANO | H9: 1600
A10: =+A9+1 -> 8 | B10: 71248162 | C10: 459584 | D10: CERRON | E10: RAMOS | F10: ANGGELA STHEFANIE | G10: VULCANO | H10: 1400
A11: =+A10+1 -> 9 | B11: 71727072 | C11: 456145 | D11: CHIMAYCO | E11: MANYARI | F11: GABRIELA ANTONELA | G11: LURIN | H11: 1700
A12: =+A11+1 -> 10 | B12: 74177006 | C12: 456099 | D12: CORONADO | E12: SALCEDO | F12: IRVIN ROBERT | G12: CRONOS | H12: 1900
A13: =+A12+1 -> 11 | B13: 74757847 | C13: 453155 | D13: CUBA | E13: CANDIA | F13: ELBER ANDRE | G13: CRONOS | H13: 1700
A14: =+A13+1 -> 12 | B14: 73073569 | C14: 457642 | D14: CURAY | E14: CORREA | F14: ANGELO ENMANUEL | G14: VULCANO | H14: 1400
A15: =+A14+1 -> 13 | B15: 72302489 | C15: 453502 | D15: DE LA PUENTE | E15: MOZOMBITE | F15: BIANCA ANGIELIN | G15: CRONOS | H15: 1900
... A59: =+A58+1 -> 57 | B59: 72397508 | C59: 459581 | D59: VIZA | E59: BAUTISTA | F59: KAROL JIMENA | G59: AREQUIPA | H59: 1600
